Workbook

Sheet Produtos Atuais
A1: Plano Atual | B1: Nº Vidas | C1: % | J1: Plano Atual | K1: Nº Vidas | L1: Valor Atual
A2: MEDICUS | B2: 150 | C2: =B2/$B$8 -> 0.35211268 | J2: =CONCATENATE(A2,CHAR(10),B2," VIDAS") -> MEDICUS 150 VIDAS | L2: 61613.46
A3: OPÇÕES | B3: 76 | C3: =B3/$B$8 -> 0.17840376 | J3: =CONCATENATE(A3,CHAR(10),B3," VIDAS") -> OPÇÕES 76 VIDAS | L3: 34268.38
A4: OPÇÕES | B4: 76 | C4: =B4/$B$8 -> 0.17840376 | J4: =CONCATENATE(A4,CHAR(10),B4," VIDAS") -> OPÇÕES 76 VIDAS | L4: 34268.38
A5: OPÇÕES | B5: 76 | C5: =B5/$B$8 -> 0.17840376 | J5: =CONCATENATE(A5,CHAR(10),B5," VIDAS") -> OPÇÕES 76 VIDAS | L5: 34268.38
A6: QUALITY | B6: 46 | C6: =B6/$B$8 -> 0.10798122 | J6: =CONCATENATE(A6,CHAR(10),B6," VIDAS") -> QUALITY 46 VIDAS | L6: 49991.19
A7: QUALITY 3 | B7: 2 | C7: =B7/$B$8 -> 0.0046948357 | J7: =CONCATENATE(A7,CHAR(10),B7," VIDAS") -> QUALITY 3 2 VIDAS | L7: 1912.74
A8: Total | B8: =SUM(B2:B7) -> 426 | C8: =SUM(C2:C7) -> 1 | J8: Total | K8: =SUM(K2:K7) -> 0 | L8: =SUM(L2:L7) -> 216322.53

Sheet Elegibilidade
A1: Elegibilidade | B1: Nº Vidas
A2: População Total | B2: =SUM(B3:B4) -> 276
A3: Feminino | B3: 151
A4: Masculino | B4: 125
A6: Funcionários | B6: 118
A7: Dependentes | B7: 158

Sheet Faixa Etária
B1: FUNCIONÁRIOS | C1: DEPENDENTES
A2: 00 - 18 | B2: 1 | C2: 72
A3: 19 - 23 | B3: 10 | C3: 8
A4: 24 - 28 | B4: 13 | C4: 5
A5: 29 - 33 | B5: 19 | C5: 8
A6: 34 - 38 | B6: 27 | C6: 15
A7: 39 - 43 | B7: 14 | C7: 21
A8: 44 - 48 | B8: 18 | C8: 14
A9: 49 - 53 | B9: 10 | C9: 7
A10: 54 - 58 | B10: 3 | C10: 1
A11: 59+ | B11: 3 | C11: 7

Sheet Equivalência
B1: Amil | C1: Player I | D1: Player II | E1: Player III | F1: Player IV | O1: a | P1: r
A3: Produto | B3: Produto 1 | C3: Produto | D3: Produto | E3: Produto | F3: Produto
A4: Enfermaria
A5: Abrangência Nacional
A6: Reembolso - Consulta | B6: R$ | C6: R$ | D6: R$ | E6: R$ | F6: R$
A8: Produto | B8: Produto 2 | C8: Produto | D8: Produto | E8: Produto | F8: Produto
A9: Apartamento
A10: Abrangência Nacional
A11: Reembolso - Consulta | B11: R$ | C11: R$ | D11: R$ | E11: R$ | F11: R$
A13: Produto | B13: Produto 3 | C13: Produto | D13: Produto | E13: Produto | F13: Produto
A14: Enfermaria
A15: Abrangência Nacional
A16: Reembolso - Consulta | B16: R$ | C16: R$ | D16: R$ | E16: R$ | F16: R$
A18: Produto | B18: Produto 4 | C18: Produto | D18: Produto | E18: Produto | F18: Produto
A19: Apartamento
A20: Abrangência Nacional
A21: Reembolso - Consulta | B21: R$ | C21: R$ | D21: R$ | E21: R$ | F21: R$
A23: Produto | B23: Produto 5 | C23: Produto | D23: Produto | E23: Produto | F23: Produto
A24: Apartamento
A25: Abrangência Nacional
A26: Reembolso - Consulta | B26: R$ | C26: R$ | D26: R$ | E26: R$ | F26: R$
A28: Produto | B28: Produto 6 | C28: Produto | D28: Produto | E28: Produto | F28: Produto
A29: Apartamento
A30: Abrangência Nacional
A31: Reembolso - Consulta | B31: R$ | C31: R$ | D31: R$ | E31: R$ | F31: R$
A33: Produto | B33: Produto 7 | C33: Produto | D33: Produto | E33: Produto | F33: Produto
A34: Apartamento
A35: Abrangência Nacional
A36: Reembolso - Consulta | B36: R$ | C36: R$ | D36: R$ | E36: R$ | F36: R$
A38: Produto | B38: Produto 8 | C38: Produto | D38: Produto | E38: Produto | F38: Produto
A39: Apartamento
A40: Abrangência Nacional
A41: Reembolso - Consulta | B41: R$ | C41: R$ | D41: R$ | E41: R$ | F41: R$
A43: Produto | B43: Produto 9 | C43: Produto | D43: Produto | E43: Produto | F43: Produto
A44: Apartamento
A45: Abrangência Nacional
A46: Reembolso - Consulta | B46: R$ | C46: R$ | D46: R$ | E46: R$ | F46: R$
A48: Produto | B48: Produto 10 | C48: Produto | D48: Produto | E48: Produto | F48: Produto
A49: Apartamento
A50: Abrangência Nacional
...

Sheet Análise Financeira CC
B1: =Equivalência!B1 -> Amil | C1: Reajuste 20% | D1: =Equivalência!C1 -> Player I | E1: =Equivalência!D1 -> Player II | F1: =Equivalência!E1 -> Player III | G1: =Equivalência!F1 -> Player IV | Q1: a | R1: r
A3: Produto | B3: =Equivalência!B3 -> Produto 1 | C3: =B3 -> Produto 1 | D3: =Equivalência!C3 -> Produto | E3: =Equivalência!D3 -> Produto | F3: =Equivalência!E3 -> Produto | G3: =Equivalência!F3 -> Produto
A4: Número de Vidas | C4: =B4 -> 0 | D4: =C4 -> 0 | E4: =D4 -> 0 | F4: =E4 -> 0 | G4: =F4 -> 0
A5: Custo Médio | C5: =B5*120% -> 0
A6: Total | B6: =B5*B4 -> 0 | C6: =C5*C4 -> 0 | D6: =D5*D4 -> 0 | E6: =E5*E4 -> 0 | F6: =F5*F4 -> 0 | G6: =G5*G4 -> 0
A8: Produto | B8: =Equivalência!B8 -> Produto 2 | C8: =B8 -> Produto 2 | D8: =Equivalência!C8 -> Produto | E8: =Equivalência!D8 -> Produto | F8: =Equivalência!E8 -> Produto | G8: =Equivalência!F8 -> Produto
A9: Número de Vidas | C9: =B9 -> 0 | D9: =C9 -> 0 | E9: =D9 -> 0 | F9: =E9 -> 0 | G9: =F9 -> 0
A10: Custo Médio | C10: =B10*120% -> 0
A11: Total | B11: =B10*B9 -> 0 | C11: =C10*C9 -> 0 | D11: =D10*D9 -> 0 | E11: =E10*E9 -> 0 | F11: =F10*F9 -> 0 | G11: =G10*G9 -> 0
A13: Produto | B13: =Equivalência!B13 -> Produto 3 | C13: =B13 -> Produto 3 | D13: =Equivalência!C13 -> Produto | E13: =Equivalência!D13 -> Produto | F13: =Equivalência!E13 -> Produto | G13: =Equivalência!F13 -> Produto
A14: Número de Vidas | C14: =B14 -> 0 | D14: =C14 -> 0 | E14: =D14 -> 0 | F14: =E14 -> 0 | G14: =F14 -> 0
A15: Custo Médio | C15: =B15*120% -> 0
A16: Total | B16: =B15*B14 -> 0 | C16: =C15*C14 -> 0 | D16: =D15*D14 -> 0 | E16: =E15*E14 -> 0 | F16: =F15*F14 -> 0 | G16: =G15*G14 -> 0
A18: Produto | B18: =Equivalência!B18 -> Produto 4 | C18: =B18 -> Produto 4 | D18: =Equivalência!C18 -> Produto | E18: =Equivalência!D18 -> Produto | F18: =Equivalência!E18 -> Produto | G18: =Equivalência!F18 -> Produto
A19: Número de Vidas | C19: =B19 -> 0 | D19: =C19 -> 0 | E19: =D19 -> 0 | F19: =E19 -> 0 | G19: =F19 -> 0
A20: Custo Médio | C20: =B20*120% -> 0
A21: Total | B21: =B20*B19 -> 0 | C21: =C20*C19 -> 0 | D21: =D20*D19 -> 0 | E21: =E20*E19 -> 0 | F21: =F20*F19 -> 0 | G21: =G20*G19 -> 0
A23: Produto | B23: =Equivalência!B23 -> Produto 5 | C23: =B23 -> Produto 5 | D23: =Equivalência!C23 -> Produto | E23: =Equivalência!D23 -> Produto | F23: =Equivalência!E23 -> Produto | G23: =Equivalência!F23 -> Produto
A24: Número de Vidas | C24: =B24 -> 0 | D24: =C24 -> 0 | E24: =D24 -> 0 | F24: =E24 -> 0 | G24: =F24 -> 0
A25: Custo Médio | C25: =B25*120% -> 0
A26: Total | B26: =B25*B24 -> 0 | C26: =C25*C24 -> 0 | D26: =D25*D24 -> 0 | E26: =E25*E24 -> 0 | F26: =F25*F24 -> 0 | G26: =G25*G24 -> 0
A28: Produto | B28: =Equivalência!B28 -> Produto 6 | C28: =B28 -> Produto 6 | D28: =Equivalência!C28 -> Produto | E28: =Equivalência!D28 -> Produto | F28: =Equivalência!E28 -> Produto | G28: =Equivalência!F28 -> Produto
A29: Número de Vidas | C29: =B29 -> 0 | D29: =C29 -> 0 | E29: =D29 -> 0 | F29: =E29 -> 0 | G29: =F29 -> 0
A30: Custo Médio | C30: =B30*120% -> 0
A31: Total | B31: =B30*B29 -> 0 | C31: =C30*C29 -> 0 | D31: =D30*D29 -> 0 | E31: =E30*E29 -> 0 | F31: =F30*F29 -> 0 | G31: =G30*G29 -> 0
A33: Produto | B33: =Equivalência!B33 -> Produto 7 | C33: =B33 -> Produto 7 | D33: =Equivalência!C33 -> Produto | E33: =Equivalência!D33 -> Produto | F33: =Equivalência!E33 -> Produto | G33: =Equivalência!F33 -> Produto
A34: Número de Vidas | C34: =B34 -> 0 | D34: =C34 -> 0 | E34: =D34 -> 0 | F34: =E34 -> 0 | G34: =F34 -> 0
A35: Custo Médio | C35: =B35*120% -> 0
A36: Total | B36: =B35*B34 -> 0 | C36: =C35*C34 -> 0 | D36: =D35*D34 -> 0 | E36: =E35*E34 -> 0 | F36: =F35*F34 -> 0 | G36: =G35*G34 -> 0
A38: Produto | B38: =Equivalência!B38 -> Produto 8 | C38: =B38 -> Produto 8 | D38: =Equivalência!C38 -> Produto | E38: =Equivalência!D38 -> Produto | F38: =Equivalência!E38 -> Produto | G38: =Equivalência!F38 -> Produto
A39: Número de Vidas | C39: =B39 -> 0 | D39: =C39 -> 0 | E39: =D39 -> 0 | F39: =E39 -> 0 | G39: =F39 -> 0
A40: Custo Médio | C40: =B40*120% -> 0
A41: Total | B41: =B40*B39 -> 0 | C41: =C40*C39 -> 0 | D41: =D40*D39 -> 0 | E41: =E40*E39 -> 0 | F41: =F40*F39 -> 0 | G41: =G40*G39 -> 0
A43: Produto | B43: =Equivalência!B43 -> Produto 9 | C43: =B43 -> Produto 9 | D43: =Equivalência!C43 -> Produto | E43: =Equivalência!D43 -> Produto | F43: =Equivalência!E43 -> Produto | G43: =Equivalência!F43 -> Produto
A44: Número de Vidas | C44: =B44 -> 0 | D44: =C44 -> 0 | E44: =D44 -> 0 | F44: =E44 -> 0 | G44: =F44 -> 0
A45: Custo Médio | C45: =B45*120% -> 0
A46: Total | B46: =B45*B44 -> 0 | C46: =C45*C44 -> 0 | D46: =D45*D44 -> 0 | E46: =E45*E44 -> 0 | F46: =F45*F44 -> 0 | G46: =G45*G44 -> 0
A48: Produto | B48: =Equivalência!B48 -> Produto 10 | C48: =B48 -> Produto 10 | D48: =Equivalência!C48 -> Produto | E48: =Equivalência!D48 -> Produto | F48: =Equivalência!E48 -> Produto | G48: =Equivalência!F48 -> Produto
A49: Número de Vidas | C49: =B49 -> 0 | D49: =C49 -> 0 | E49: =D49 -> 0 | F49: =E49 -> 0 | G49: =F49 -> 0
A50: Custo Médio | C50: =B50*120% -> 0
...

Sheet Impacto Financeiro CC
B1: =Equivalência!B1 -> Amil | C1: ='Análise Financeira CC'!C1 -> Reajuste 20% | D1: =Equivalência!C1 -> Player I | E1: =Equivalência!D1 -> Player II | F1: =Equivalência!E1 -> Player III | G1: =Equivalência!F1 -> Player IV | Q1: a | R1: r
A3: Total de Vidas | B3: ='Análise Financeira CC'!B4+'Análise Financeira CC'!B9+'Análise Financeira CC'!B14+'Análise Financeira CC'!B19+'Análise Financeira CC'!B24+'Análise Financeira CC'!B49+'Análise Financeira CC'!B44+'Análise Financeira CC'!B39+'Análise Financeira CC'!B34+'Análise Financeira CC'!B29 -> 0 | C3: ='Análise Financeira CC'!C4+'Análise Financeira CC'!C9+'Análise Financeira CC'!C14+'Análise Financeira CC'!C19+'Análise Financeira CC'!C24+'Análise Financeira CC'!C49+'Análise Financeira CC'!C44+'Análise Financeira CC'!C39+'Análise Financeira CC'!C34+'Análise Financeira CC'!C29 -> 0 | D3: ='Análise Financeira CC'!D4+'Análise Financeira CC'!D9+'Análise Financeira CC'!D14+'Análise Financeira CC'!D19+'Análise Financeira CC'!D24+'Análise Financeira CC'!D49+'Análise Financeira CC'!D44+'Análise Financeira CC'!D39+'Análise Financeira CC'!D34+'Análise Financeira CC'!D29 -> 0 | E3: ='Análise Financeira CC'!E4+'Análise Financeira CC'!E9+'Análise Financeira CC'!E14+'Análise Financeira CC'!E19+'Análise Financeira CC'!E24+'Análise Financeira CC'!E49+'Análise Financeira CC'!E44+'Análise Financeira CC'!E39+'Análise Financeira CC'!E34+'Análise Financeira CC'!E29 -> 0 | F3: ='Análise Financeira CC'!F4+'Análise Financeira CC'!F9+'Análise Financeira CC'!F14+'Análise Financeira CC'!F19+'Análise Financeira CC'!F24+'Análise Financeira CC'!F49+'Análise Financeira CC'!F44+'Análise Financeira CC'!F39+'Análise Financeira CC'!F34+'Análise Financeira CC'!F29 -> 0 | G3: ='Análise Financeira CC'!G4+'Análise Financeira CC'!G9+'Análise Financeira CC'!G14+'Análise Financeira CC'!G19+'Análise Financeira CC'!G24+'Análise Financeira CC'!G49+'Análise Financeira CC'!G44+'Análise Financeira CC'!G39+'Análise Financeira CC'!G34+'Análise Financeira CC'!G29 -> 0
A4: Total da Fatura (Mensal) | B4: ='Análise Financeira CC'!B6+'Análise Financeira CC'!B11+'Análise Financeira CC'!B16+'Análise Financeira CC'!B21+'Análise Financeira CC'!B26+'Análise Financeira CC'!B51+'Análise Financeira CC'!B46+'Análise Financeira CC'!B41+'Análise Financeira CC'!B36+'Análise Financeira CC'!B31 -> 0 | C4: ='Análise Financeira CC'!C6+'Análise Financeira CC'!C11+'Análise Financeira CC'!C16+'Análise Financeira CC'!C21+'Análise Financeira CC'!C26+'Análise Financeira CC'!C51+'Análise Financeira CC'!C46+'Análise Financeira CC'!C41+'Análise Financeira CC'!C36+'Análise Financeira CC'!C31 -> 0 | D4: ='Análise Financeira CC'!D6+'Análise Financeira CC'!D11+'Análise Financeira CC'!D16+'Análise Financeira CC'!D21+'Análise Financeira CC'!D26+'Análise Financeira CC'!D51+'Análise Financeira CC'!D46+'Análise Financeira CC'!D41+'Análise Financeira CC'!D36+'Análise Financeira CC'!D31 -> 0 | E4: ='Análise Financeira CC'!E6+'Análise Financeira CC'!E11+'Análise Financeira CC'!E16+'Análise Financeira CC'!E21+'Análise Financeira CC'!E26+'Análise Financeira CC'!E51+'Análise Financeira CC'!E46+'Análise Financeira CC'!E41+'Análise Financeira CC'!E36+'Análise Financeira CC'!E31 -> 0 | F4: ='Análise Financeira CC'!F6+'Análise Financeira CC'!F11+'Análise Financeira CC'!F16+'Análise Financeira CC'!F21+'Análise Financeira CC'!F26+'Análise Financeira CC'!F51+'Análise Financeira CC'!F46+'Análise Financeira CC'!F41+'Análise Financeira CC'!F36+'Análise Financeira CC'!F31 -> 0 | G4: ='Análise Financeira CC'!G6+'Análise Financeira CC'!G11+'Análise Financeira CC'!G16+'Análise Financeira CC'!G21+'Análise Financeira CC'!G26+'Análise Financeira CC'!G51+'Análise Financeira CC'!G46+'Análise Financeira CC'!G41+'Análise Financeira CC'!G36+'Análise Financeira CC'!G31 -> 0
A5: Total da Fatura (Anual) | B5: =B4*12 -> 0 | C5: =C4*12 -> 0 | D5: =D4*12 -> 0 | E5: =E4*12 -> 0 | F5: =F4*12 -> 0 | G5: =G4*12 -> 0
A6: Impacto Financeiro (Mensal) | C6: =C4-B4 -> 0 | D6: =D4-$C$4 -> 0 | E6: =E4-$C$4 -> 0 | F6: =F4-$C$4 -> 0 | G6: =G4-$C$4 -> 0
A7: Impacto Financeiro (Anual) | C7: =C5-B5 -> 0 | D7: =D5-$C$5 -> 0 | E7: =E5-$C$5 -> 0 | F7: =F5-$C$5 -> 0 | G7: =G5-$C$5 -> 0
A8: Impacto Financeiro ( em %) | C8: =C5/B5-1 -> #DIV/0! | D8: =D5/$C$5-1 -> #DIV/0! | E8: =E5/$C$5-1 -> #DIV/0! | F8: =F5/$C$5-1 -> #DIV/0! | G8: =G5/$C$5-1 -> #DIV/0!

Sheet Análise Financeira SC
B1: =Equivalência!B1 -> Amil | C1: Reajuste 20% | D1: =Equivalência!C1 -> Player I | E1: =Equivalência!D1 -> Player II | F1: =Equivalência!E1 -> Player III | G1: =Equivalência!F1 -> Player IV | Q1: a | R1: r
A3: Produto | B3: =Equivalência!B3 -> Produto 1 | C3: =B3 -> Produto 1 | D3: =Equivalência!C3 -> Produto | E3: =Equivalência!D3 -> Produto | F3: =Equivalência!E3 -> Produto | G3: =Equivalência!F3 -> Produto
A4: Número de Vidas | B4: ='Análise Financeira CC'!B4 -> 0 | C4: =B4 -> 0 | D4: =C4 -> 0 | E4: =D4 -> 0 | F4: =E4 -> 0 | G4: =F4 -> 0
A5: Custo Médio | B5: ='Análise Financeira CC'!B5 -> 0 | C5: =B5*120% -> 0
A6: Total | B6: =B5*B4 -> 0 | C6: =C5*C4 -> 0 | D6: =D5*D4 -> 0 | E6: =E5*E4 -> 0 | F6: =F5*F4 -> 0 | G6: =G5*G4 -> 0
A8: Produto | B8: =Equivalência!B8 -> Produto 2 | C8: =B8 -> Produto 2 | D8: =Equivalência!C8 -> Produto | E8: =Equivalência!D8 -> Produto | F8: =Equivalência!E8 -> Produto | G8: =Equivalência!F8 -> Produto
A9: Número de Vidas | B9: ='Análise Financeira CC'!B9 -> 0 | C9: =B9 -> 0 | D9: =C9 -> 0 | E9: =D9 -> 0 | F9: =E9 -> 0 | G9: =F9 -> 0
A10: Custo Médio | B10: ='Análise Financeira CC'!B10 -> 0 | C10: =B10*120% -> 0
A11: Total | B11: =B10*B9 -> 0 | C11: =C10*C9 -> 0 | D11: =D10*D9 -> 0 | E11: =E10*E9 -> 0 | F11: =F10*F9 -> 0 | G11: =G10*G9 -> 0
A13: Produto | B13: =Equivalência!B13 -> Produto 3 | C13: =B13 -> Produto 3 | D13: =Equivalência!C13 -> Produto | E13: =Equivalência!D13 -> Produto | F13: =Equivalência!E13 -> Produto | G13: =Equivalência!F13 -> Produto
A14: Número de Vidas | B14: ='Análise Financeira CC'!B14 -> 0 | C14: =B14 -> 0 | D14: =C14 -> 0 | E14: =D14 -> 0 | F14: =E14 -> 0 | G14: =F14 -> 0
A15: Custo Médio | B15: ='Análise Financeira CC'!B15 -> 0 | C15: =B15*120% -> 0
A16: Total | B16: =B15*B14 -> 0 | C16: =C15*C14 -> 0 | D16: =D15*D14 -> 0 | E16: =E15*E14 -> 0 | F16: =F15*F14 -> 0 | G16: =G15*G14 -> 0
A18: Produto | B18: =Equivalência!B18 -> Produto 4 | C18: =B18 -> Produto 4 | D18: =Equivalência!C18 -> Produto | E18: =Equivalência!D18 -> Produto | F18: =Equivalência!E18 -> Produto | G18: =Equivalência!F18 -> Produto
A19: Número de Vidas | B19: ='Análise Financeira CC'!B19 -> 0 | C19: =B19 -> 0 | D19: =C19 -> 0 | E19: =D19 -> 0 | F19: =E19 -> 0 | G19: =F19 -> 0
A20: Custo Médio | B20: ='Análise Financeira CC'!B20 -> 0 | C20: =B20*120% -> 0
A21: Total | B21: =B20*B19 -> 0 | C21: =C20*C19 -> 0 | D21: =D20*D19 -> 0 | E21: =E20*E19 -> 0 | F21: =F20*F19 -> 0 | G21: =G20*G19 -> 0
A23: Produto | B23: =Equivalência!B23 -> Produto 5 | C23: =B23 -> Produto 5 | D23: =Equivalência!C23 -> Produto | E23: =Equivalência!D23 -> Produto | F23: =Equivalência!E23 -> Produto | G23: =Equivalência!F23 -> Produto
A24: Número de Vidas | B24: ='Análise Financeira CC'!B24 -> 0 | C24: =B24 -> 0 | D24: =C24 -> 0 | E24: =D24 -> 0 | F24: =E24 -> 0 | G24: =F24 -> 0
A25: Custo Médio | B25: ='Análise Financeira CC'!B25 -> 0 | C25: =B25*120% -> 0
A26: Total | B26: =B25*B24 -> 0 | C26: =C25*C24 -> 0 | D26: =D25*D24 -> 0 | E26: =E25*E24 -> 0 | F26: =F25*F24 -> 0 | G26: =G25*G24 -> 0
A28: Produto | B28: =Equivalência!B28 -> Produto 6 | C28: =B28 -> Produto 6 | D28: =Equivalência!C28 -> Produto | E28: =Equivalência!D28 -> Produto | F28: =Equivalência!E28 -> Produto | G28: =Equivalência!F28 -> Produto
A29: Número de Vidas | B29: ='Análise Financeira CC'!B29 -> 0 | C29: =B29 -> 0 | D29: =C29 -> 0 | E29: =D29 -> 0 | F29: =E29 -> 0 | G29: =F29 -> 0
A30: Custo Médio | B30: ='Análise Financeira CC'!B30 -> 0 | C30: =B30*120% -> 0
A31: Total | B31: =B30*B29 -> 0 | C31: =C30*C29 -> 0 | D31: =D30*D29 -> 0 | E31: =E30*E29 -> 0 | F31: =F30*F29 -> 0 | G31: =G30*G29 -> 0
A33: Produto | B33: =Equivalência!B33 -> Produto 7 | C33: =B33 -> Produto 7 | D33: =Equivalência!C33 -> Produto | E33: =Equivalência!D33 -> Produto | F33: =Equivalência!E33 -> Produto | G33: =Equivalência!F33 -> Produto
A34: Número de Vidas | B34: ='Análise Financeira CC'!B34 -> 0 | C34: =B34 -> 0 | D34: =C34 -> 0 | E34: =D34 -> 0 | F34: =E34 -> 0 | G34: =F34 -> 0
A35: Custo Médio | B35: ='Análise Financeira CC'!B35 -> 0 | C35: =B35*120% -> 0
A36: Total | B36: =B35*B34 -> 0 | C36: =C35*C34 -> 0 | D36: =D35*D34 -> 0 | E36: =E35*E34 -> 0 | F36: =F35*F34 -> 0 | G36: =G35*G34 -> 0
A38: Produto | B38: =Equivalência!B38 -> Produto 8 | C38: =B38 -> Produto 8 | D38: =Equivalência!C38 -> Produto | E38: =Equivalência!D38 -> Produto | F38: =Equivalência!E38 -> Produto | G38: =Equivalência!F38 -> Produto
A39: Número de Vidas | B39: ='Análise Financeira CC'!B39 -> 0 | C39: =B39 -> 0 | D39: =C39 -> 0 | E39: =D39 -> 0 | F39: =E39 -> 0 | G39: =F39 -> 0
A40: Custo Médio | B40: ='Análise Financeira CC'!B40 -> 0 | C40: =B40*120% -> 0
A41: Total | B41: =B40*B39 -> 0 | C41: =C40*C39 -> 0 | D41: =D40*D39 -> 0 | E41: =E40*E39 -> 0 | F41: =F40*F39 -> 0 | G41: =G40*G39 -> 0
A43: Produto | B43: =Equivalência!B43 -> Produto 9 | C43: =B43 -> Produto 9 | D43: =Equivalência!C43 -> Produto | E43: =Equivalência!D43 -> Produto | F43: =Equivalência!E43 -> Produto | G43: =Equivalência!F43 -> Produto
A44: Número de Vidas | B44: ='Análise Financeira CC'!B44 -> 0 | C44: =B44 -> 0 | D44: =C44 -> 0 | E44: =D44 -> 0 | F44: =E44 -> 0 | G44: =F44 -> 0
A45: Custo Médio | B45: ='Análise Financeira CC'!B45 -> 0 | C45: =B45*120% -> 0
A46: Total | B46: =B45*B44 -> 0 | C46: =C45*C44 -> 0 | D46: =D45*D44 -> 0 | E46: =E45*E44 -> 0 | F46: =F45*F44 -> 0 | G46: =G45*G44 -> 0
A48: Produto | B48: =Equivalência!B48 -> Produto 10 | C48: =B48 -> Produto 10 | D48: =Equivalência!C48 -> Produto | E48: =Equivalência!D48 -> Produto | F48: =Equivalência!E48 -> Produto | G48: =Equivalência!F48 -> Produto
A49: Número de Vidas | B49: ='Análise Financeira CC'!B49 -> 0 | C49: =B49 -> 0 | D49: =C49 -> 0 | E49: =D49 -> 0 | F49: =E49 -> 0 | G49: =F49 -> 0
A50: Custo Médio | B50: ='Análise Financeira CC'!B50 -> 0 | C50: =B50*120% -> 0
...

Sheet Impacto Financeiro SC
B1: =Equivalência!B1 -> Amil | C1: ='Análise Financeira SC'!C1 -> Reajuste 20% | D1: =Equivalência!C1 -> Player I | E1: =Equivalência!D1 -> Player II | F1: =Equivalência!E1 -> Player III | G1: =Equivalência!F1 -> Player IV | Q1: a | R1: r
A3: Total de Vidas | B3: ='Análise Financeira SC'!B4+'Análise Financeira SC'!B9+'Análise Financeira SC'!B14+'Análise Financeira SC'!B19+'Análise Financeira SC'!B24+'Análise Financeira SC'!B49+'Análise Financeira SC'!B44+'Análise Financeira SC'!B39+'Análise Financeira SC'!B34+'Análise Financeira SC'!B29 -> 0 | C3: ='Análise Financeira SC'!C4+'Análise Financeira SC'!C9+'Análise Financeira SC'!C14+'Análise Financeira SC'!C19+'Análise Financeira SC'!C24+'Análise Financeira SC'!C49+'Análise Financeira SC'!C44+'Análise Financeira SC'!C39+'Análise Financeira SC'!C34+'Análise Financeira SC'!C29 -> 0 | D3: ='Análise Financeira SC'!D4+'Análise Financeira SC'!D9+'Análise Financeira SC'!D14+'Análise Financeira SC'!D19+'Análise Financeira SC'!D24+'Análise Financeira SC'!D49+'Análise Financeira SC'!D44+'Análise Financeira SC'!D39+'Análise Financeira SC'!D34+'Análise Financeira SC'!D29 -> 0 | E3: ='Análise Financeira SC'!E4+'Análise Financeira SC'!E9+'Análise Financeira SC'!E14+'Análise Financeira SC'!E19+'Análise Financeira SC'!E24+'Análise Financeira SC'!E49+'Análise Financeira SC'!E44+'Análise Financeira SC'!E39+'Análise Financeira SC'!E34+'Análise Financeira SC'!E29 -> 0 | F3: ='Análise Financeira SC'!F4+'Análise Financeira SC'!F9+'Análise Financeira SC'!F14+'Análise Financeira SC'!F19+'Análise Financeira SC'!F24+'Análise Financeira SC'!F49+'Análise Financeira SC'!F44+'Análise Financeira SC'!F39+'Análise Financeira SC'!F34+'Análise Financeira SC'!F29 -> 0 | G3: ='Análise Financeira SC'!G4+'Análise Financeira SC'!G9+'Análise Financeira SC'!G14+'Análise Financeira SC'!G19+'Análise Financeira SC'!G24+'Análise Financeira SC'!G49+'Análise Financeira SC'!G44+'Análise Financeira SC'!G39+'Análise Financeira SC'!G34+'Análise Financeira SC'!G29 -> 0
A4: Total da Fatura (Mensal) | B4: ='Análise Financeira SC'!B6+'Análise Financeira SC'!B11+'Análise Financeira SC'!B16+'Análise Financeira SC'!B21+'Análise Financeira SC'!B26+'Análise Financeira SC'!B51+'Análise Financeira SC'!B46+'Análise Financeira SC'!B41+'Análise Financeira SC'!B36+'Análise Financeira SC'!B31 -> 0 | C4: ='Análise Financeira SC'!C6+'Análise Financeira SC'!C11+'Análise Financeira SC'!C16+'Análise Financeira SC'!C21+'Análise Financeira SC'!C26+'Análise Financeira SC'!C51+'Análise Financeira SC'!C46+'Análise Financeira SC'!C41+'Análise Financeira SC'!C36+'Análise Financeira SC'!C31 -> 0 | D4: ='Análise Financeira SC'!D6+'Análise Financeira SC'!D11+'Análise Financeira SC'!D16+'Análise Financeira SC'!D21+'Análise Financeira SC'!D26+'Análise Financeira SC'!D51+'Análise Financeira SC'!D46+'Análise Financeira SC'!D41+'Análise Financeira SC'!D36+'Análise Financeira SC'!D31 -> 0 | E4: ='Análise Financeira SC'!E6+'Análise Financeira SC'!E11+'Análise Financeira SC'!E16+'Análise Financeira SC'!E21+'Análise Financeira SC'!E26+'Análise Financeira SC'!E51+'Análise Financeira SC'!E46+'Análise Financeira SC'!E41+'Análise Financeira SC'!E36+'Análise Financeira SC'!E31 -> 0 | F4: ='Análise Financeira SC'!F6+'Análise Financeira SC'!F11+'Análise Financeira SC'!F16+'Análise Financeira SC'!F21+'Análise Financeira SC'!F26+'Análise Financeira SC'!F51+'Análise Financeira SC'!F46+'Análise Financeira SC'!F41+'Análise Financeira SC'!F36+'Análise Financeira SC'!F31 -> 0 | G4: ='Análise Financeira SC'!G6+'Análise Financeira SC'!G11+'Análise Financeira SC'!G16+'Análise Financeira SC'!G21+'Análise Financeira SC'!G26+'Análise Financeira SC'!G51+'Análise Financeira SC'!G46+'Análise Financeira SC'!G41+'Análise Financeira SC'!G36+'Análise Financeira SC'!G31 -> 0
A5: Total da Fatura (Anual) | B5: =B4*12 -> 0 | C5: =C4*12 -> 0 | D5: =D4*12 -> 0 | E5: =E4*12 -> 0 | F5: =F4*12 -> 0 | G5: =G4*12 -> 0
A6: Impacto Financeiro (Mensal) | C6: =C4-B4 -> 0 | D6: =D4-$C$4 -> 0 | E6: =E4-$C$4 -> 0 | F6: =F4-$C$4 -> 0 | G6: =G4-$C$4 -> 0
A7: Impacto Financeiro (Anual) | C7: =C5-B5 -> 0 | D7: =D5-$C$5 -> 0 | E7: =E5-$C$5 -> 0 | F7: =F5-$C$5 -> 0 | G7: =G5-$C$5 -> 0
A8: Impacto Financeiro ( em %) | C8: =C5/B5-1 -> #DIV/0! | D8: =D5/$C$5-1 -> #DIV/0! | E8: =E5/$C$5-1 -> #DIV/0! | F8: =F5/$C$5-1 -> #DIV/0! | G8: =G5/$C$5-1 -> #DIV/0!

Sheet Economia
A1: VALOR ATUAL | B1: VALOR OFERTADO | C1: REDUÇÃO MENSAL | D1: PRÓ-RATA (X MESES ATE O ANIVERSAIO DA APOLICE)
C2: =A2-B2 -> 0 | D2: =C2*9 -> 0
A4: VALOR ATUAL | B4: VALOR OFERTADO | C4: ECONOMIA ANUAL | D4: ECONOMIA 1° ANO
A5: =A2*113% -> 0 | B5: =B2 -> 0 | C5: =A5-B5 -> 0 | D5: =C5*12 -> 0
A7: VALOR ATUAL | B7: VALOR OFERTADO | C7: ECONOMIA BIENAL | D7: ECONOMIA 2° ANO
A8: =A5*113% -> 0 | B8: =B2 -> 0 | C8: =A8-B8 -> 0 | D8: =C8*12 -> 0
D10: ECONOMIA BIÊNIO
D11: =D5+D8 -> 0
